Traceback (most recent call last):
  File "C:\Users\beck\miniforge3\envs\jubook\lib\site-packages\jupyter_cache\executors\utils.py", line 64, in single_nb_execution
    **kwargs,
  File "C:\Users\beck\miniforge3\envs\jubook\lib\site-packages\nbclient\client.py", line 1204, in execute
    return NotebookClient(nb=nb, resources=resources, km=km, **kwargs).execute()
  File "C:\Users\beck\miniforge3\envs\jubook\lib\site-packages\nbclient\util.py", line 84, in wrapped
    return just_run(coro(*args, **kwargs))
  File "C:\Users\beck\miniforge3\envs\jubook\lib\site-packages\nbclient\util.py", line 62, in just_run
    return loop.run_until_complete(coro)
  File "C:\Users\beck\miniforge3\envs\jubook\lib\asyncio\base_events.py", line 573, in run_until_complete
    return future.result()
  File "C:\Users\beck\miniforge3\envs\jubook\lib\site-packages\nbclient\client.py", line 664, in async_execute
    cell, index, execution_count=self.code_cells_executed + 1
  File "C:\Users\beck\miniforge3\envs\jubook\lib\site-packages\nbclient\client.py", line 965, in async_execute_cell
    await self._check_raise_for_error(cell, cell_index, exec_reply)
  File "C:\Users\beck\miniforge3\envs\jubook\lib\site-packages\nbclient\client.py", line 862, in _check_raise_for_error
    raise CellExecutionError.from_cell_and_msg(cell, exec_reply_content)
nbclient.exceptions.CellExecutionError: An error occurred while executing the following cell:
------------------
# Point source illumination intensity

def E_ps(x2, y2, xs, ys, h, phi_tot): # point source half-space spotlight
    E = phi_tot / 2 / np.pi * h / ((x2 - xs)**2 + (y2 - ys)**2 + h**2)**(3/2)
    return E

ax = 5 # depth
by = 4 # width
h  = 2 # height above working plane

Nx, Ny = (int(100*a), int(100*b))
x2 = np.linspace(0, ax, Nx)
y2 = np.linspace(0, by, Ny)

res_2D_p = np.zeros((Ny, Nx))
for nx, xx in enumerate(x2):
    for ny, yy in enumerate(y2):
        res_2D_p[ny, nx] = E_ps(xx, yy, xs=2.5, ys=2, h=h, phi_tot=1000)
------------------

[1;31m---------------------------------------------------------------------------[0m
[1;31mNameError[0m                                 Traceback (most recent call last)
[1;32m~\AppData\Local\Temp\ipykernel_29300\149637092.py[0m in [0;36m<module>[1;34m[0m
[0;32m      9[0m [0mh[0m  [1;33m=[0m [1;36m2[0m [1;31m# height above working plane[0m[1;33m[0m[1;33m[0m[0m
[0;32m     10[0m [1;33m[0m[0m
[1;32m---> 11[1;33m [0mNx[0m[1;33m,[0m [0mNy[0m [1;33m=[0m [1;33m([0m[0mint[0m[1;33m([0m[1;36m100[0m[1;33m*[0m[0ma[0m[1;33m)[0m[1;33m,[0m [0mint[0m[1;33m([0m[1;36m100[0m[1;33m*[0m[0mb[0m[1;33m)[0m[1;33m)[0m[1;33m[0m[1;33m[0m[0m
[0m[0;32m     12[0m [0mx2[0m [1;33m=[0m [0mnp[0m[1;33m.[0m[0mlinspace[0m[1;33m([0m[1;36m0[0m[1;33m,[0m [0max[0m[1;33m,[0m [0mNx[0m[1;33m)[0m[1;33m[0m[1;33m[0m[0m
[0;32m     13[0m [0my2[0m [1;33m=[0m [0mnp[0m[1;33m.[0m[0mlinspace[0m[1;33m([0m[1;36m0[0m[1;33m,[0m [0mby[0m[1;33m,[0m [0mNy[0m[1;33m)[0m[1;33m[0m[1;33m[0m[0m

[1;31mNameError[0m: name 'a' is not defined
NameError: name 'a' is not defined

